Workbook
Name Slicer_Booking_Source: #N/A
Name Slicer_Guest_Gender: #N/A
Name Slicer_HOTEL: #N/A
Name Slicer_Months__Checkin_Date: #N/A
Name Slicer_Room_Type: #N/A
Name Slicer_Satisfication_level: #N/A
Name Slicer_Travel_Purpose: #N/A
Name Slicer_Would_Recommend: #N/A
Name Slicer_Would_Recommend1: #N/A
Name Slicer_Years__Checkin_Date: #N/A

Sheet PIVOT ANALYSIS
A1: GRAND FOOD | B1: =SUM(Table2[Food_Quality]) -> 6024 | D1: HOTEL | E1: FOOD QUALITY | G1: SAFETY MEASURE | I1: ROOM CLEAN | K1: AMENITIES
A2: GRAND SAFETY | B2: =SUM(Table2[Safety_Measures]) -> 5961 | D2: {=_xlfn.UNIQUE(Table2[Hotel_Name])} -> Grand Heritage | E2: =SUMIF(Table2[Hotel_Name],'PIVOT ANALYSIS'!$D2,Table2[Food_Quality]) -> 1287 | F2: =$E2/'PIVOT ANALYSIS'!$B$1 -> 0.21364542 | G2: =SUMIF(Table2[Hotel_Name],'PIVOT ANALYSIS'!$D2,Table2[Safety_Measures]) -> 1211 | H2: =$G2/'PIVOT ANALYSIS'!$B$2 -> 0.20315383 | I2: =SUMIF(Table2[Hotel_Name],'PIVOT ANALYSIS'!$D2,Table2[Room_Cleanliness]) -> 1261 | J2: =$I2/'PIVOT ANALYSIS'!$B$3 -> 0.21111669 | K2: =SUMIF(Table2[Hotel_Name],'PIVOT ANALYSIS'!$D2,Table2[Amenities_Satisfaction]) -> 1284 | L2: =$K2/'PIVOT ANALYSIS'!$B$4 -> 0.21453634
A3: GRAND ROOM CLEAN | B3: =SUM(Table2[Room_Cleanliness]) -> 5973 | D3: OceanView Resort | E3: =SUMIF(Table2[Hotel_Name],'PIVOT ANALYSIS'!$D3,Table2[Food_Quality]) -> 1106 | F3: =$E3/'PIVOT ANALYSIS'!$B$1 -> 0.18359894 | G3: =SUMIF(Table2[Hotel_Name],'PIVOT ANALYSIS'!$D3,Table2[Safety_Measures]) -> 1109 | H3: =$G3/'PIVOT ANALYSIS'!$B$2 -> 0.18604261 | I3: =SUMIF(Table2[Hotel_Name],'PIVOT ANALYSIS'!$D3,Table2[Room_Cleanliness]) -> 1108 | J3: =$I3/'PIVOT ANALYSIS'!$B$3 -> 0.18550142 | K3: =SUMIF(Table2[Hotel_Name],'PIVOT ANALYSIS'!$D3,Table2[Amenities_Satisfaction]) -> 1098 | L3: =$K3/'PIVOT ANALYSIS'!$B$4 -> 0.18345865
A4: GRAND AMENITIES | B4: =SUM(Table2[Amenities_Satisfaction]) -> 5985 | D4: City Lights Hotel | E4: =SUMIF(Table2[Hotel_Name],'PIVOT ANALYSIS'!$D4,Table2[Food_Quality]) -> 1164 | F4: =$E4/'PIVOT ANALYSIS'!$B$1 -> 0.19322709 | G4: =SUMIF(Table2[Hotel_Name],'PIVOT ANALYSIS'!$D4,Table2[Safety_Measures]) -> 1159 | H4: =$G4/'PIVOT ANALYSIS'!$B$2 -> 0.19443046 | I4: =SUMIF(Table2[Hotel_Name],'PIVOT ANALYSIS'!$D4,Table2[Room_Cleanliness]) -> 1139 | J4: =$I4/'PIVOT ANALYSIS'!$B$3 -> 0.19069144 | K4: =SUMIF(Table2[Hotel_Name],'PIVOT ANALYSIS'!$D4,Table2[Amenities_Satisfaction]) -> 1114 | L4: =$K4/'PIVOT ANALYSIS'!$B$4 -> 0.186132
D5: Hilltop Inn | E5: =SUMIF(Table2[Hotel_Name],'PIVOT ANALYSIS'!$D5,Table2[Food_Quality]) -> 1212 | F5: =$E5/'PIVOT ANALYSIS'!$B$1 -> 0.20119522 | G5: =SUMIF(Table2[Hotel_Name],'PIVOT ANALYSIS'!$D5,Table2[Safety_Measures]) -> 1162 | H5: =$G5/'PIVOT ANALYSIS'!$B$2 -> 0.19493374 | I5: =SUMIF(Table2[Hotel_Name],'PIVOT ANALYSIS'!$D5,Table2[Room_Cleanliness]) -> 1190 | J5: =$I5/'PIVOT ANALYSIS'!$B$3 -> 0.19922987 | K5: =SUMIF(Table2[Hotel_Name],'PIVOT ANALYSIS'!$D5,Table2[Amenities_Satisfaction]) -> 1212 | L5: =$K5/'PIVOT ANALYSIS'!$B$4 -> 0.20250627
D6: Palm Grove Stay | E6: =SUMIF(Table2[Hotel_Name],'PIVOT ANALYSIS'!$D6,Table2[Food_Quality]) -> 1255 | F6: =$E6/'PIVOT ANALYSIS'!$B$1 -> 0.20833333 | G6: =SUMIF(Table2[Hotel_Name],'PIVOT ANALYSIS'!$D6,Table2[Safety_Measures]) -> 1320 | H6: =$G6/'PIVOT ANALYSIS'!$B$2 -> 0.22143936 | I6: =SUMIF(Table2[Hotel_Name],'PIVOT ANALYSIS'!$D6,Table2[Room_Cleanliness]) -> 1275 | J6: =$I6/'PIVOT ANALYSIS'!$B$3 -> 0.21346057 | K6: =SUMIF(Table2[Hotel_Name],'PIVOT ANALYSIS'!$D6,Table2[Amenities_Satisfaction]) -> 1277 | L6: =$K6/'PIVOT ANALYSIS'!$B$4 -> 0.21336675
A10: HOTEL | B10: TOTAL_GUESTS | D10: =A10 -> HOTEL | E10: =B10 -> TOTAL_GUESTS
A11: Palm Grove Stay | B11: 434 | D11: =A11 -> Palm Grove Stay | E11: =B11 -> 434
A12: Grand Heritage | B12: 411 | D12: =A12 -> Grand Heritage | E12: =B12 -> 411
A13: Hilltop Inn | B13: 403 | D13: =A13 -> Hilltop Inn | E13: =B13 -> 403
A14: City Lights Hotel | B14: 380 | D14: =A14 -> City Lights Hotel | E14: =B14 -> 380
A15: OceanView Resort | B15: 372 | D15: =A15 -> OceanView Resort | E15: =B15 -> 372
A16: Grand Total | B16: 2000 | D16: TOTAL | E16: =SUM(E11:E15) -> 2000
A28: TOTAL_GUESTS | B28: AGE CRITERA
A29: AGE CRITERIA | B29: Female | C29: Male | D29: Other | F29: =A29 -> AGE CRITERIA | G29: =B29 -> Female | H29: =C29 -> Male | I29: =D29 -> Other
A30: Adults | B30: 129 | C30: 113 | D30: 121 | F30: =A30 -> Adults | G30: =B30 -> 129 | H30: =C30 -> 113 | I30: =D30 -> 121
A31: Middle Aged Adults | B31: 188 | C31: 198 | D31: 183 | F31: =A31 -> Middle Aged Adults | G31: =B31 -> 188 | H31: =C31 -> 198 | I31: =D31 -> 183
A32: Senior | B32: 249 | C32: 247 | D32: 249 | F32: =A32 -> Senior | G32: =B32 -> 249 | H32: =C32 -> 247 | I32: =D32 -> 249
A33: Young Adults | B33: 97 | C33: 124 | D33: 102 | F33: =A33 -> Young Adults | G33: =B33 -> 97 | H33: =C33 -> 124 | I33: =D33 -> 102
A48: SATIFICATION | B48: TOTAL_GUESTS | D48: =A48 -> SATIFICATION | E48: =B48 -> TOTAL_GUESTS
A49: AVERAGE | B49: 1016 | D49: =A49 -> AVERAGE | E49: =B49 -> 1016
A50: GOOD | B50: 36 | D50: =A50 -> GOOD | E50: =B50 -> 36
A51: GREAT | B51: 1 | D51: =A51 -> GREAT | E51: =B51 -> 1
A52: POOR | B52: 947
A53: Grand Total | B53: 2000
A67: GENDER | B67: Count of Guest_ID | D67: =A67 -> GENDER | E67: TOTAL GUEST
A68: Female | B68: 663 | D68: =A68 -> Female | E68: =B68 -> 663
A69: Male | B69: 682 | D69: =A69 -> Male | E69: =B69 -> 682
A70: Other | B70: 655 | D70: =A70 -> Other | E70: =B70 -> 655
A87: GENDER | B87: Count of Guest_ID | E87: GENDER | F87: TOTAL GUESTS
A88: Jan | B88: 182 | E88: =A88 -> Jan | F88: =B88 -> 182
A89: Feb | B89: 181 | E89: =A89 -> Feb | F89: =B89 -> 181
A90: Mar | B90: 163 | E90: =A90 -> Mar | F90: =B90 -> 163
A91: Apr | B91: 147 | E91: =A91 -> Apr | F91: =B91 -> 147
A92: May | B92: 149 | E92: =A92 -> May | F92: =B92 -> 149
A93: Jun | B93: 168 | E93: =A93 -> Jun | F93: =B93 -> 168
A94: Jul | B94: 181 | E94: =A94 -> Jul | F94: =B94 -> 181
A95: Aug | B95: 180 | E95: =A95 -> Aug | F95: =B95 -> 180
A96: Sep | B96: 164 | E96: =A96 -> Sep | F96: =B96 -> 164
A97: Oct | B97: 161 | E97: =A97 -> Oct | F97: =B97 -> 161
...

Sheet SUMMARY

Sheet QUALITY ANALYSIS
A3: HOTEL | B3: FOOD_QUALITY | E3: =A3 -> HOTEL | F3: =B3 -> FOOD_QUALITY
A4: City Lights Hotel | B4: 0.19322709 | E4: =A4 -> City Lights Hotel | F4: =B4 -> 0.19322709
A5: Grand Heritage | B5: 0.21364542 | E5: =A5 -> Grand Heritage | F5: =B5 -> 0.21364542
A6: Hilltop Inn | B6: 0.20119522 | E6: =A6 -> Hilltop Inn | F6: =B6 -> 0.20119522
A7: OceanView Resort | B7: 0.18359894 | E7: =A7 -> OceanView Resort | F7: =B7 -> 0.18359894
A8: Palm Grove Stay | B8: 0.20833333 | E8: =A8 -> Palm Grove Stay | F8: =B8 -> 0.20833333
A11: HOTEL | B11: SAFETY MEASURES | E11: =A11 -> HOTEL | F11: =B11 -> SAFETY MEASURES
A12: City Lights Hotel | B12: 0.19443046 | E12: =A12 -> City Lights Hotel | F12: =B12 -> 0.19443046
A13: Grand Heritage | B13: 0.20315383 | E13: =A13 -> Grand Heritage | F13: =B13 -> 0.20315383
A14: Hilltop Inn | B14: 0.19493374 | E14: =A14 -> Hilltop Inn | F14: =B14 -> 0.19493374
A15: OceanView Resort | B15: 0.18604261 | E15: =A15 -> OceanView Resort | F15: =B15 -> 0.18604261
A16: Palm Grove Stay | B16: 0.22143936 | E16: =A16 -> Palm Grove Stay | F16: =B16 -> 0.22143936
O17: HOTEL | P17: FOOD QUALITY | Q17: SAFETY MEASURE | R17: ROOM CLEANLINESS | S17: AMENITIES
O18: Grand Heritage | P18: 0.21364542 | Q18: 0.20315383 | R18: 0.21111669 | S18: 0.21453634
O19: OceanView Resort | P19: 0.18359894 | Q19: 0.18604261 | R19: 0.18550142 | S19: 0.18345865
A20: HOTEL | B20: ROOM_CLEANLINESS | E20: =A20 -> HOTEL | F20: =B20 -> ROOM_CLEANLINESS | O20: City Lights Hotel | P20: 0.19322709 | Q20: 0.19443046 | R20: 0.19069144 | S20: 0.186132
A21: City Lights Hotel | B21: 0.19069144 | E21: =A21 -> City Lights Hotel | F21: =B21 -> 0.19069144 | O21: Hilltop Inn | P21: 0.20119522 | Q21: 0.19493374 | R21: 0.19922987 | S21: 0.20250627
A22: Grand Heritage | B22: 0.21111669 | E22: =A22 -> Grand Heritage | F22: =B22 -> 0.21111669 | O22: Palm Grove Stay | P22: 0.20833333 | Q22: 0.22143936 | R22: 0.21346057 | S22: 0.21336675
A23: Hilltop Inn | B23: 0.19922987 | E23: =A23 -> Hilltop Inn | F23: =B23 -> 0.19922987
A24: OceanView Resort | B24: 0.18550142 | E24: =A24 -> OceanView Resort | F24: =B24 -> 0.18550142
A25: Palm Grove Stay | B25: 0.21346057 | E25: =A25 -> Palm Grove Stay | F25: =B25 -> 0.21346057
A29: HOTEL | B29: AMENITIES SATISFICATION | E29: =A29 -> HOTEL | F29: =B29 -> AMENITIES SATISFICATION
A30: City Lights Hotel | B30: 0.186132 | E30: =A30 -> City Lights Hotel | F30: =B30 -> 0.186132
A31: Grand Heritage | B31: 0.21453634 | E31: =A31 -> Grand Heritage | F31: =B31 -> 0.21453634
A32: Hilltop Inn | B32: 0.20250627 | E32: =A32 -> Hilltop Inn | F32: =B32 -> 0.20250627
A33: OceanView Resort | B33: 0.18345865 | E33: =A33 -> OceanView Resort | F33: =B33 -> 0.18345865
A34: Palm Grove Stay | B34: 0.21336675 | E34: =A34 -> Palm Grove Stay | F34: =B34 -> 0.21336675

Sheet DATA ANALYSIS
A9: HOTEL | B9: TOTAL_GUESTS
A10: Grand Heritage | B10: 218
A11: Palm Grove Stay | B11: 217
A12: City Lights Hotel | B12: 210
A13: Hilltop Inn | B13: 195
A14: OceanView Resort | B14: 189
A18: AGE CRITERIA | B18: Female | C18: Male | D18: Other
A19: Adults | B19: 76 | C19: 61 | D19: 56
A20: Middle Aged Adults | B20: 101 | C20: 102 | D20: 89
A21: Senior | B21: 133 | C21: 114 | D21: 128
A22: Young Adults | B22: 59 | C22: 63 | D22: 47
A25: GENDER | B25: TOTAL GUEST
A26: Female | B26: 369
A27: Male | B27: 340
A28: Other | B28: 320
A31: SATIFICATION | B31: TOTAL_GUESTS
A32: AVERAGE | B32: 524
A33: GOOD | B33: 18
A34: POOR | B34: 487
A37: GENDER | B37: TOTAL GUESTS
A38: Jan | B38: 88
A39: Feb | B39: 89
A40: Mar | B40: 86
A41: Apr | B41: 77
A42: May | B42: 77
A43: Jun | B43: 85
A44: Jul | B44: 92
A45: Aug | B45: 101
A46: Sep | B46: 94
A47: Oct | B47: 81
A48: Nov | B48: 77
A49: Dec | B49: 82
A52: BOOKING SOURCE | B52: TOTAL COUNT
A53: App | B53: 276
A54: Travel Agent | B54: 261
A55: Walk-in | B55: 250
A56: Website | B56: 242
A59: HOTEL | B59: Sum of Room_Cleanliness
A60: City Lights Hotel | B60: 629
A61: Grand Heritage | B61: 665
...

Sheet Guest_Feedback_Hospitality_Indu
A1: Feedback_ID | B1: Guest_ID | C1: Guest_Name | D1: Hotel_Name | E1: Room_Type | F1: Checkin_Date | G1: Checkout_Date | H1: Stay_Duration | I1: Booking_Source | J1: Travel_Purpose | K1: Room_Cleanliness | L1: Staff_Courtesy | M1: Food_Quality | N1: Checkin_Experience | O1: Checkout_Experience | P1: Amenities_Satisfaction | Q1: Value_for_Money | R1: Safety_Measures | S1: WiFi_Quality | T1: Noise_Levels | U1: Would_Recommend | V1: Feedback_Source | W1: Additional_Comments | X1: Guest_Gender | Y1: Guest_Age | Z1: Feedback_Date | AA1: Age_Criteria | AB1: Satification_points | AC1: Satisfication_level
A2: 1 | B2: 41989 | C2: Theresa Perez | D2: Grand Heritage | E2: Single | F2: 45334 | G2: 45491 | H2: 7 | I2: Website | J2: Business | K2: 2 | L2: 5 | M2: 1 | N2: 1 | O2: 5 | P2: 3 | Q2: 2 | R2: 3 | S2: 4 | T2: 5 | U2: Yes | V2: Email | W2: Great stay | X2: Male | Y2: 20 | Z2: 45491 | AA2: {=_xlfn.IFS(AND(Table2[[#This Row],[Guest_Age]]>=18,Table2[[#This Row],[Guest_Age]]<=25),"Young Adults",AND(Table2[[#This Row],[Guest_Age]]>=26,Table2[[#This Row],[Guest_Age]]<=35),"Adults",AND(Table2[[#This Row],[Guest_Age]]>=36,Table2[[#This Row],[Guest_Age]]<=50),"Middle Aged Adults",Table2[[#This Row],[Guest_Age]]>50,"Senior")} -> Young Adults | AB2: =AVERAGE(Table2[[#This Row],[Room_Cleanliness]],Table2[[#This Row],[Staff_Courtesy]],Table2[[#This Row],[Food_Quality]],Table2[[#This Row],[Checkin_Experience]],Table2[[#This Row],[Checkout_Experience]],Table2[[#This Row],[Amenities_Satisfaction]],Table2[[#This Row],[Value_for_Money]],Table2[[#This Row],[Safety_Measures]],Table2[[#This Row],[WiFi_Quality]],Table2[[#This Row],[Noise_Levels]]) -> 3.1 | AC2: {=_xlfn.IFS(Table2[[#This Row],[Satification_points]]>=4.5,"GREAT",AND(Table2[[#This Row],[Satification_points]]>=4,Table2[[#This Row],[Satification_points]]<4.5),"GOOD",AND(Table2[[#This Row],[Satification_points]]>=3,Table2[[#This Row],[Satification_points]]<4),"AVERAGE",Table2[[#This Row],[Satification_points]]<3,"POOR")} -> AVERAGE
A3: 2 | B3: 99245 | C3: Melanie Mccarthy | D3: OceanView Resort | E3: Double | F3: 45515 | G3: 45516 | H3: 8 | I3: Website | J3: Conference | K3: 3 | L3: 4 | M3: 5 | N3: 5 | O3: 2 | P3: 5 | Q3: 3 | R3: 3 | S3: 2 | T3: 1 | U3: No | V3: Feedback Form | W3: Average | X3: Other | Y3: 46 | Z3: 45516 | AA3: {=_xlfn.IFS(AND(Table2[[#This Row],[Guest_Age]]>=18,Table2[[#This Row],[Guest_Age]]<=25),"Young Adults",AND(Table2[[#This Row],[Guest_Age]]>=26,Table2[[#This Row],[Guest_Age]]<=35),"Adults",AND(Table2[[#This Row],[Guest_Age]]>=36,Table2[[#This Row],[Guest_Age]]<=50),"Middle Aged Adults",Table2[[#This Row],[Guest_Age]]>50,"Senior")} -> Middle Aged Adults | AB3: =AVERAGE(Table2[[#This Row],[Room_Cleanliness]],Table2[[#This Row],[Staff_Courtesy]],Table2[[#This Row],[Food_Quality]],Table2[[#This Row],[Checkin_Experience]],Table2[[#This Row],[Checkout_Experience]],Table2[[#This Row],[Amenities_Satisfaction]],Table2[[#This Row],[Value_for_Money]],Table2[[#This Row],[Safety_Measures]],Table2[[#This Row],[WiFi_Quality]],Table2[[#This Row],[Noise_Levels]]) -> 3.3 | AC3: {=_xlfn.IFS(Table2[[#This Row],[Satification_points]]>=4.5,"GREAT",AND(Table2[[#This Row],[Satification_points]]>=4,Table2[[#This Row],[Satification_points]]<4.5),"GOOD",AND(Table2[[#This Row],[Satification_points]]>=3,Table2[[#This Row],[Satification_points]]<4),"AVERAGE",Table2[[#This Row],[Satification_points]]<3,"POOR")} -> AVERAGE
A4: 3 | B4: 83251 | C4: Robert Johnson | D4: City Lights Hotel | E4: Double | F4: 45094 | G4: 45257 | H4: 7 | I4: App | J4: Transit | K4: 1 | L4: 1 | M4: 5 | N4: 1 | O4: 4 | P4: 2 | Q4: 5 | R4: 5 | S4: 3 | T4: 3 | U4: No | V4: Email | W4: Great stay | X4: Female | Y4: 68 | Z4: 45257 | AA4: {=_xlfn.IFS(AND(Table2[[#This Row],[Guest_Age]]>=18,Table2[[#This Row],[Guest_Age]]<=25),"Young Adults",AND(Table2[[#This Row],[Guest_Age]]>=26,Table2[[#This Row],[Guest_Age]]<=35),"Adults",AND(Table2[[#This Row],[Guest_Age]]>=36,Table2[[#This Row],[Guest_Age]]<=50),"Middle Aged Adults",Table2[[#This Row],[Guest_Age]]>50,"Senior")} -> Senior | AB4: =AVERAGE(Table2[[#This Row],[Room_Cleanliness]],Table2[[#This Row],[Staff_Courtesy]],Table2[[#This Row],[Food_Quality]],Table2[[#This Row],[Checkin_Experience]],Table2[[#This Row],[Checkout_Experience]],Table2[[#This Row],[Amenities_Satisfaction]],Table2[[#This Row],[Value_for_Money]],Table2[[#This Row],[Safety_Measures]],Table2[[#This Row],[WiFi_Quality]],Table2[[#This Row],[Noise_Levels]]) -> 3 | AC4: {=_xlfn.IFS(Table2[[#This Row],[Satification_points]]>=4.5,"GREAT",AND(Table2[[#This Row],[Satification_points]]>=4,Table2[[#This Row],[Satification_points]]<4.5),"GOOD",AND(Table2[[#This Row],[Satification_points]]>=3,Table2[[#This Row],[Satification_points]]<4),"AVERAGE",Table2[[#This Row],[Satification_points]]<3,"POOR")} -> AVERAGE
A5: 4 | B5: 83963 | C5: Melissa Farrell | D5: City Lights Hotel | E5: Family | F5: 45548 | G5: 45549 | H5: 3 | I5: Website | J5: Other | K5: 2 | L5: 2 | M5: 1 | N5: 4 | O5: 4 | P5: 5 | Q5: 2 | R5: 1 | S5: 2 | T5: 5 | U5: Yes | V5: App Review | W5: Poor service | X5: Other | Y5: 47 | Z5: 45549 | AA5: {=_xlfn.IFS(AND(Table2[[#This Row],[Guest_Age]]>=18,Table2[[#This Row],[Guest_Age]]<=25),"Young Adults",AND(Table2[[#This Row],[Guest_Age]]>=26,Table2[[#This Row],[Guest_Age]]<=35),"Adults",AND(Table2[[#This Row],[Guest_Age]]>=36,Table2[[#This Row],[Guest_Age]]<=50),"Middle Aged Adults",Table2[[#This Row],[Guest_Age]]>50,"Senior")} -> Middle Aged Adults | AB5: =AVERAGE(Table2[[#This Row],[Room_Cleanliness]],Table2[[#This Row],[Staff_Courtesy]],Table2[[#This Row],[Food_Quality]],Table2[[#This Row],[Checkin_Experience]],Table2[[#This Row],[Checkout_Experience]],Table2[[#This Row],[Amenities_Satisfaction]],Table2[[#This Row],[Value_for_Money]],Table2[[#This Row],[Safety_Measures]],Table2[[#This Row],[WiFi_Quality]],Table2[[#This Row],[Noise_Levels]]) -> 2.8 | AC5: {=_xlfn.IFS(Table2[[#This Row],[Satification_points]]>=4.5,"GREAT",AND(Table2[[#This Row],[Satification_points]]>=4,Table2[[#This Row],[Satification_points]]<4.5),"GOOD",AND(Table2[[#This Row],[Satification_points]]>=3,Table2[[#This Row],[Satification_points]]<4),"AVERAGE",Table2[[#This Row],[Satification_points]]<3,"POOR")} -> POOR
A6: 5 | B6: 78322 | C6: Morgan Pierce | D6: Hilltop Inn | E6: Family | F6: 45633 | G6: 45634 | H6: 7 | I6: Travel Agent | J6: Other | K6: 3 | L6: 3 | M6: 5 | N6: 1 | O6: 4 | P6: 3 | Q6: 3 | R6: 2 | S6: 2 | T6: 3 | U6: Yes | V6: Feedback Form | W6: Poor service | X6: Male | Y6: 29 | Z6: 45634 | AA6: {=_xlfn.IFS(AND(Table2[[#This Row],[Guest_Age]]>=18,Table2[[#This Row],[Guest_Age]]<=25),"Young Adults",AND(Table2[[#This Row],[Guest_Age]]>=26,Table2[[#This Row],[Guest_Age]]<=35),"Adults",AND(Table2[[#This Row],[Guest_Age]]>=36,Table2[[#This Row],[Guest_Age]]<=50),"Middle Aged Adults",Table2[[#This Row],[Guest_Age]]>50,"Senior")} -> Adults | AB6: =AVERAGE(Table2[[#This Row],[Room_Cleanliness]],Table2[[#This Row],[Staff_Courtesy]],Table2[[#This Row],[Food_Quality]],Table2[[#This Row],[Checkin_Experience]],Table2[[#This Row],[Checkout_Experience]],Table2[[#This Row],[Amenities_Satisfaction]],Table2[[#This Row],[Value_for_Money]],Table2[[#This Row],[Safety_Measures]],Table2[[#This Row],[WiFi_Quality]],Table2[[#This Row],[Noise_Levels]]) -> 2.9 | AC6: {=_xlfn.IFS(Table2[[#This Row],[Satification_points]]>=4.5,"GREAT",AND(Table2[[#This Row],[Satification_points]]>=4,Table2[[#This Row],[Satification_points]]<4.5),"GOOD",AND(Table2[[#This Row],[Satification_points]]>=3,Table2[[#This Row],[Satification_points]]<4),"AVERAGE",Table2[[#This Row],[Satification_points]]<3,"POOR")} -> POOR
A7: 6 | B7: 24454 | C7: Todd Arellano | D7: City Lights Hotel | E7: Family | F7: 45093 | G7: 45094 | H7: 1 | I7: Walk-in | J7: Other | K7: 4 | L7: 3 | M7: 1 | N7: 3 | O7: 3 | P7: 4 | Q7: 4 | R7: 3 | S7: 1 | T7: 2 | U7: Yes | V7: Feedback Form | W7: Average | X7: Other | Y7: 38 | Z7: 45530 | AA7: {=_xlfn.IFS(AND(Table2[[#This Row],[Guest_Age]]>=18,Table2[[#This Row],[Guest_Age]]<=25),"Young Adults",AND(Table2[[#This Row],[Guest_Age]]>=26,Table2[[#This Row],[Guest_Age]]<=35),"Adults",AND(Table2[[#This Row],[Guest_Age]]>=36,Table2[[#This Row],[Guest_Age]]<=50),"Middle Aged Adults",Table2[[#This Row],[Guest_Age]]>50,"Senior")} -> Middle Aged Adults | AB7: =AVERAGE(Table2[[#This Row],[Room_Cleanliness]],Table2[[#This Row],[Staff_Courtesy]],Table2[[#This Row],[Food_Quality]],Table2[[#This Row],[Checkin_Experience]],Table2[[#This Row],[Checkout_Experience]],Table2[[#This Row],[Amenities_Satisfaction]],Table2[[#This Row],[Value_for_Money]],Table2[[#This Row],[Safety_Measures]],Table2[[#This Row],[WiFi_Quality]],Table2[[#This Row],[Noise_Levels]]) -> 2.8 | AC7: {=_xlfn.IFS(Table2[[#This Row],[Satification_points]]>=4.5,"GREAT",AND(Table2[[#This Row],[Satification_points]]>=4,Table2[[#This Row],[Satification_points]]<4.5),"GOOD",AND(Table2[[#This Row],[Satification_points]]>=3,Table2[[#This Row],[Satification_points]]<4),"AVERAGE",Table2[[#This Row],[Satification_points]]<3,"POOR")} -> POOR
A8: 7 | B8: 11377 | C8: Robert Gates | D8: Palm Grove Stay | E8: Suite | F8: 45459 | G8: 45460 | H8: 5 | I8: Travel Agent | J8: Leisure | K8: 1 | L8: 1 | M8: 1 | N8: 2 | O8: 4 | P8: 5 | Q8: 4 | R8: 5 | S8: 2 | T8: 2 | U8: Yes | V8: Email | W8: Average | X8: Female | Y8: 19 | Z8: 45596 | AA8: {=_xlfn.IFS(AND(Table2[[#This Row],[Guest_Age]]>=18,Table2[[#This Row],[Guest_Age]]<=25),"Young Adults",AND(Table2[[#This Row],[Guest_Age]]>=26,Table2[[#This Row],[Guest_Age]]<=35),"Adults",AND(Table2[[#This Row],[Guest_Age]]>=36,Table2[[#This Row],[Guest_Age]]<=50),"Middle Aged Adults",Table2[[#This Row],[Guest_Age]]>50,"Senior")} -> Young Adults | AB8: =AVERAGE(Table2[[#This Row],[Room_Cleanliness]],Table2[[#This Row],[Staff_Courtesy]],Table2[[#This Row],[Food_Quality]],Table2[[#This Row],[Checkin_Experience]],Table2[[#This Row],[Checkout_Experience]],Table2[[#This Row],[Amenities_Satisfaction]],Table2[[#This Row],[Value_for_Money]],Table2[[#This Row],[Safety_Measures]],Table2[[#This Row],[WiFi_Quality]],Table2[[#This Row],[Noise_Levels]]) -> 2.7 | AC8: {=_xlfn.IFS(Table2[[#This Row],[Satification_points]]>=4.5,"GREAT",AND(Table2[[#This Row],[Satification_points]]>=4,Table2[[#This Row],[Satification_points]]<4.5),"GOOD",AND(Table2[[#This Row],[Satification_points]]>=3,Table2[[#This Row],[Satification_points]]<4),"AVERAGE",Table2[[#This Row],[Satification_points]]<3,"POOR")} -> POOR
A9: 8 | B9: 45523 | C9: Tammy Smith | D9: City Lights Hotel | E9: Suite | F9: 45091 | G9: 45615 | H9: 9 | I9: Travel Agent | J9: Transit | K9: 2 | L9: 5 | M9: 4 | N9: 5 | O9: 2 | P9: 5 | Q9: 5 | R9: 5 | S9: 5 | T9: 4 | U9: No | V9: In-person | W9: Average | X9: Other | Y9: 69 | Z9: 45615 | AA9: {=_xlfn.IFS(AND(Table2[[#This Row],[Guest_Age]]>=18,Table2[[#This Row],[Guest_Age]]<=25),"Young Adults",AND(Table2[[#This Row],[Guest_Age]]>=26,Table2[[#This Row],[Guest_Age]]<=35),"Adults",AND(Table2[[#This Row],[Guest_Age]]>=36,Table2[[#This Row],[Guest_Age]]<=50),"Middle Aged Adults",Table2[[#This Row],[Guest_Age]]>50,"Senior")} -> Senior | AB9: =AVERAGE(Table2[[#This Row],[Room_Cleanliness]],Table2[[#This Row],[Staff_Courtesy]],Table2[[#This Row],[Food_Quality]],Table2[[#This Row],[Checkin_Experience]],Table2[[#This Row],[Checkout_Experience]],Table2[[#This Row],[Amenities_Satisfaction]],Table2[[#This Row],[Value_for_Money]],Table2[[#This Row],[Safety_Measures]],Table2[[#This Row],[WiFi_Quality]],Table2[[#This Row],[Noise_Levels]]) -> 4.2 | AC9: {=_xlfn.IFS(Table2[[#This Row],[Satification_points]]>=4.5,"GREAT",AND(Table2[[#This Row],[Satification_points]]>=4,Table2[[#This Row],[Satification_points]]<4.5),"GOOD",AND(Table2[[#This Row],[Satification_points]]>=3,Table2[[#This Row],[Satification_points]]<4),"AVERAGE",Table2[[#This Row],[Satification_points]]<3,"POOR")} -> GOOD
A10: 9 | B10: 40807 | C10: Matthew Mcbride | D10: Palm Grove Stay | E10: Single | F10: 45568 | G10: 45569 | H10: 2 | I10: App | J10: Business | K10: 2 | L10: 5 | M10: 2 | N10: 3 | O10: 3 | P10: 1 | Q10: 4 | R10: 1 | S10: 4 | T10: 2 | U10: No | V10: App Review | W10: Will visit again | X10: Other | Y10: 67 | Z10: 45569 | AA10: {=_xlfn.IFS(AND(Table2[[#This Row],[Guest_Age]]>=18,Table2[[#This Row],[Guest_Age]]<=25),"Young Adults",AND(Table2[[#This Row],[Guest_Age]]>=26,Table2[[#This Row],[Guest_Age]]<=35),"Adults",AND(Table2[[#This Row],[Guest_Age]]>=36,Table2[[#This Row],[Guest_Age]]<=50),"Middle Aged Adults",Table2[[#This Row],[Guest_Age]]>50,"Senior")} -> Senior | AB10: =AVERAGE(Table2[[#This Row],[Room_Cleanliness]],Table2[[#This Row],[Staff_Courtesy]],Table2[[#This Row],[Food_Quality]],Table2[[#This Row],[Checkin_Experience]],Table2[[#This Row],[Checkout_Experience]],Table2[[#This Row],[Amenities_Satisfaction]],Table2[[#This Row],[Value_for_Money]],Table2[[#This Row],[Safety_Measures]],Table2[[#This Row],[WiFi_Quality]],Table2[[#This Row],[Noise_Levels]]) -> 2.7 | AC10: {=_xlfn.IFS(Table2[[#This Row],[Satification_points]]>=4.5,"GREAT",AND(Table2[[#This Row],[Satification_points]]>=4,Table2[[#This Row],[Satification_points]]<4.5),"GOOD",AND(Table2[[#This Row],[Satification_points]]>=3,Table2[[#This Row],[Satification_points]]<4),"AVERAGE",Table2[[#This Row],[Satification_points]]<3,"POOR")} -> POOR
A11: 10 | B11: 28467 | C11: Mr. Philip Hawkins | D11: Grand Heritage | E11: Suite | F11: 45188 | G11: 45247 | H11: 3 | I11: Travel Agent | J11: Other | K11: 1 | L11: 2 | M11: 3 | N11: 5 | O11: 2 | P11: 4 | Q11: 3 | R11: 4 | S11: 1 | T11: 1 | U11: No | V11: Email | W11: Great stay | X11: Female | Y11: 33 | Z11: 45247 | AA11: {=_xlfn.IFS(AND(Table2[[#This Row],[Guest_Age]]>=18,Table2[[#This Row],[Guest_Age]]<=25),"Young Adults",AND(Table2[[#This Row],[Guest_Age]]>=26,Table2[[#This Row],[Guest_Age]]<=35),"Adults",AND(Table2[[#This Row],[Guest_Age]]>=36,Table2[[#This Row],[Guest_Age]]<=50),"Middle Aged Adults",Table2[[#This Row],[Guest_Age]]>50,"Senior")} -> Adults | AB11: =AVERAGE(Table2[[#This Row],[Room_Cleanliness]],Table2[[#This Row],[Staff_Courtesy]],Table2[[#This Row],[Food_Quality]],Table2[[#This Row],[Checkin_Experience]],Table2[[#This Row],[Checkout_Experience]],Table2[[#This Row],[Amenities_Satisfaction]],Table2[[#This Row],[Value_for_Money]],Table2[[#This Row],[Safety_Measures]],Table2[[#This Row],[WiFi_Quality]],Table2[[#This Row],[Noise_Levels]]) -> 2.6 | AC11: {=_xlfn.IFS(Table2[[#This Row],[Satification_points]]>=4.5,"GREAT",AND(Table2[[#This Row],[Satification_points]]>=4,Table2[[#This Row],[Satification_points]]<4.5),"GOOD",AND(Table2[[#This Row],[Satification_points]]>=3,Table2[[#This Row],[Satification_points]]<4),"AVERAGE",Table2[[#This Row],[Satification_points]]<3,"POOR")} -> POOR
A12: 11 | B12: 47177 | C12: Scott Johnson | D12: Palm Grove Stay | E12: Single | F12: 45490 | G12: 45491 | H12: 9 | I12: Travel Agent | J12: Business | K12: 4 | L12: 1 | M12: 3 | N12: 5 | O12: 4 | P12: 1 | Q12: 5 | R12: 3 | S12: 2 | T12: 2 | U12: No | V12: Feedback Form | W12: Needs improvement | X12: Female | Y12: 49 | Z12: 45491 | AA12: {=_xlfn.IFS(AND(Table2[[#This Row],[Guest_Age]]>=18,Table2[[#This Row],[Guest_Age]]<=25),"Young Adults",AND(Table2[[#This Row],[Guest_Age]]>=26,Table2[[#This Row],[Guest_Age]]<=35),"Adults",AND(Table2[[#This Row],[Guest_Age]]>=36,Table2[[#This Row],[Guest_Age]]<=50),"Middle Aged Adults",Table2[[#This Row],[Guest_Age]]>50,"Senior")} -> Middle Aged Adults | AB12: =AVERAGE(Table2[[#This Row],[Room_Cleanliness]],Table2[[#This Row],[Staff_Courtesy]],Table2[[#This Row],[Food_Quality]],Table2[[#This Row],[Checkin_Experience]],Table2[[#This Row],[Checkout_Experience]],Table2[[#This Row],[Amenities_Satisfaction]],Table2[[#This Row],[Value_for_Money]],Table2[[#This Row],[Safety_Measures]],Table2[[#This Row],[WiFi_Quality]],Table2[[#This Row],[Noise_Levels]]) -> 3 | AC12: {=_xlfn.IFS(Table2[[#This Row],[Satification_points]]>=4.5,"GREAT",AND(Table2[[#This Row],[Satification_points]]>=4,Table2[[#This Row],[Satification_points]]<4.5),"GOOD",AND(Table2[[#This Row],[Satification_points]]>=3,Table2[[#This Row],[Satification_points]]<4),"AVERAGE",Table2[[#This Row],[Satification_points]]<3,"POOR")} -> AVERAGE
A13: 12 | B13: 22287 | C13: Veronica Rojas | D13: OceanView Resort | E13: Double | F13: 45187 | G13: 45329 | H13: 3 | I13: App | J13: Business | K13: 4 | L13: 3 | M13: 2 | N13: 1 | O13: 3 | P13: 1 | Q13: 1 | R13: 4 | S13: 1 | T13: 4 | U13: No | V13: In-person | W13: Needs improvement | X13: Male | Y13: 45 | Z13: 45506 | AA13: {=_xlfn.IFS(AND(Table2[[#This Row],[Guest_Age]]>=18,Table2[[#This Row],[Guest_Age]]<=25),"Young Adults",AND(Table2[[#This Row],[Guest_Age]]>=26,Table2[[#This Row],[Guest_Age]]<=35),"Adults",AND(Table2[[#This Row],[Guest_Age]]>=36,Table2[[#This Row],[Guest_Age]]<=50),"Middle Aged Adults",Table2[[#This Row],[Guest_Age]]>50,"Senior")} -> Middle Aged Adults | AB13: =AVERAGE(Table2[[#This Row],[Room_Cleanliness]],Table2[[#This Row],[Staff_Courtesy]],Table2[[#This Row],[Food_Quality]],Table2[[#This Row],[Checkin_Experience]],Table2[[#This Row],[Checkout_Experience]],Table2[[#This Row],[Amenities_Satisfaction]],Table2[[#This Row],[Value_for_Money]],Table2[[#This Row],[Safety_Measures]],Table2[[#This Row],[WiFi_Quality]],Table2[[#This Row],[Noise_Levels]]) -> 2.4 | AC13: {=_xlfn.IFS(Table2[[#This Row],[Satification_points]]>=4.5,"GREAT",AND(Table2[[#This Row],[Satification_points]]>=4,Table2[[#This Row],[Satification_points]]<4.5),"GOOD",AND(Table2[[#This Row],[Satification_points]]>=3,Table2[[#This Row],[Satification_points]]<4),"AVERAGE",Table2[[#This Row],[Satification_points]]<3,"POOR")} -> POOR
... A2001: 2000 | B2001: 14283 | C2001: Sarah Smith | D2001: Hilltop Inn | E2001: Double | F2001: 45356 | G2001: 45659 | H2001: 8 | I2001: Travel Agent | J2001: Transit | K2001: 5 | L2001: 2 | M2001: 4 | N2001: 2 | O2001: 4 | P2001: 3 | Q2001: 2 | R2001: 3 | S2001: 2 | T2001: 4 | U2001: No | V2001: Online Survey | W2001: Great stay | X2001: Male | Y2001: 28 | Z2001: 45659 | AA2001: {=_xlfn.IFS(AND(Table2[[#This Row],[Guest_Age]]>=18,Table2[[#This Row],[Guest_Age]]<=25),"Young Adults",AND(Table2[[#This Row],[Guest_Age]]>=26,Table2[[#This Row],[Guest_Age]]<=35),"Adults",AND(Table2[[#This Row],[Guest_Age]]>=36,Table2[[#This Row],[Guest_Age]]<=50),"Middle Aged Adults",Table2[[#This Row],[Guest_Age]]>50,"Senior")} -> Adults | AB2001: =AVERAGE(Table2[[#This Row],[Room_Cleanliness]],Table2[[#This Row],[Staff_Courtesy]],Table2[[#This Row],[Food_Quality]],Table2[[#This Row],[Checkin_Experience]],Table2[[#This Row],[Checkout_Experience]],Table2[[#This Row],[Amenities_Satisfaction]],Table2[[#This Row],[Value_for_Money]],Table2[[#This Row],[Safety_Measures]],Table2[[#This Row],[WiFi_Quality]],Table2[[#This Row],[Noise_Levels]]) -> 3.1 | AC2001: {=_xlfn.IFS(Table2[[#This Row],[Satification_points]]>=4.5,"GREAT",AND(Table2[[#This Row],[Satification_points]]>=4,Table2[[#This Row],[Satification_points]]<4.5),"GOOD",AND(Table2[[#This Row],[Satification_points]]>=3,Table2[[#This Row],[Satification_points]]<4),"AVERAGE",Table2[[#This Row],[Satification_points]]<3,"POOR")} -> AVERAGE
